
<!DOCTYPE html>
<html>
<head>
<meta charset="utf-8">
<meta name="robots" content="index, follow">
<meta name='description' content='aardio 编程语言文档 - try catch 容错语句'>
<meta http-equiv='content-language' content='zh-cn'>
<title>aardio 编程语言文档 - try catch 容错语句</title> 
<link rel="stylesheet" href="../../css/markdown.css" tppabs="https://www.aardio.com/zh-cn/doc/css/markdown.css">
<script src="../../js/prism.js" tppabs="https://www.aardio.com/zh-cn/doc/js/prism.js"></script>
<link rel="stylesheet" href="../../../../../lib.baomitu.com/font-awesome/6.6.0/css/fontawesome.min.css" tppabs="https://lib.baomitu.com/font-awesome/6.6.0/css/fontawesome.min.css">
<link rel="stylesheet" href="../../../../../lib.baomitu.com/font-awesome/6.6.0/css/solid.min.css" tppabs="https://lib.baomitu.com/font-awesome/6.6.0/css/solid.min.css">
</head>
<body class="markdown-body"><a id="back-to-home" href="../../index.htm" tppabs="https://www.aardio.com/zh-cn/doc/" title="aardio 编程语言文档首页"><i class="fas fa-home" id="home-icon"></i><i class="fas fa-robot" id="ai-icon" style="display: none;"></i><span id="aardio-document-home">aardio 文档</span></a>
<h1>try catch 容错语句</h1>

<p>相关链接：</p>

<ul>
<li><a href="blocks.html" tppabs="https://www.aardio.com/zh-cn/doc/language-reference/statements/blocks.html">语句块</a> </li>
<li><a href="../builtin-function/call.html" tppabs="https://www.aardio.com/zh-cn/doc/language-reference/builtin-function/call.html">容错调用函数：call</a><br></li>
</ul>

<p>实际上在 aardio 中 try 语句使用不多。</p>

<p>aardio 并不提倡大量的抛出或处理异常，也较少需要使用 try 语句。</p>

<p>aardio 函数通常会利用多返回值检测并处理错误，大多数执行成功会返回非 null 值的函数在执行失败时会返回 <code>null, 错误信息或错误代码</code>, 也就是说检测到第一个返回值为 null 就可以从第二个返回值获取到错误原因。这种方式编码与处理错误相对来说比较简单并易于维护。</p>

<p>try 语句尝试执行一个语句块，遇到错误则退出 try 语句块而不是中断 aardio 程序。  如果使用了 catch 语句块就可以在执行代码抛出异常时时捕获错误( catch 语句是可选的 )。</p>

<p>示例如下：  </p>

<pre><code class="aardio language-aardio">import console;

try{
    b=&quot;aaaaaaaaaaaa&quot; *2
    console.log(&quot;错误会中断try语句块&quot;)
}
catch(e){ //catch部分可以省略
    console.log( &quot;错误信息：&quot;,e )
    //在这里可以调用debug库
    //在栈释放以前调用错误处理 
    //所以可以调用debug库中的函数收集错误相关的信息
}

console.log(&quot;错误不会中断程序&quot;)
console.pause();
</code></pre>

<p>错误信息不一定要是一个字符串,传递给 error 的任何信息都会被catch 捕获。</p>

<p>示例：</p>

<pre><code class="aardio language-aardio">try{
    error( {a=2;b=3} ) //error显式抛出一个异常
    console.log(&quot;错误会中断try语句块&quot;)
}
catch(e){ //catch部分可以省略
    console.log( &quot;错误信息：&quot;,e.a,e.b) 
}
</code></pre>

<p>容错语句是允许多重嵌套的，一个容错语句允许包含另一个容错语句。为了清晰地表示嵌套的层次，建议根据嵌套的层次使用 tab 制表符缩进代码。  </p>

<p>try catch 语句需要遵守以下规则：</p>

<ol>
<li><p>在 aardio 中 <code>try catch</code> 的行为更像一个立即执行的匿名函数。</p>

<ul>
<li>在 <code>try ... catch</code> 语句内部使用 <code>return</code> 语句将会中断并退出 <code>try ... catch</code> 语句自身（并非退出包含 <code>try ... catch</code> 语句的函数）。</li>
<li>不能在 <code>try ... catch</code> 语句内部对包含 <code>try ... catch</code> 语句的外部循环使用 <code>break</code> 或 <code>continue</code> 语句 。<br></li>
<li>try catch 语句块内可以使用语句外部的 owner 参数，但是不能使用语句外部的  <code>...</code> 参数。可以提前使用 <code>var args = {...}</code> 将不定参数转换为数组，在 try catch 语句块内用 <code>table.unpackArgs( args )</code> 函数展开。<br></li>
</ul></li>
<li><p>禁止在 catch 语句中再次调用 error 语句，<br>
如果需要在抛出异常前插入一些代码，在执行这些插入的代码以后继续抛出异常，那么更好的选择在 global.onError 事件中添加代码。<br>
层。</p></li>
</ol>

<p><a href="https://www.aardio.com/zh-cn/doc/language-reference/statements/try.md">Markdown 格式</a></p>

</body> 
</html>